Workbook

Sheet 月別サマリー
A1: 年月 | B1: 収入合計 | C1: 支出合計 | D1: 収支
A2: 2026-08 | B2: 1841160 | C2: 1826962 | D2: 14198

Sheet 収支データ
A1: 日付 | B1: 種別 | C1: カテゴリ | D1: 金額 | E1: メモ | F1: 年月 | G1: 大区分 | H1: 集計フラグ
A2: 46264.625 | B2: 支出 | C2: 惣菜・弁当 | D2: 162 | F2: =TEXT(A2,"yyyy-mm") | G2: =IF(B2="支出",IFERROR(VLOOKUP(C2,設定!$A$2:$B$200,2,FALSE),"その他"),"") | H2: =IF(B2="支出",IFERROR(VLOOKUP(C2,設定!$A$2:$C$200,3,FALSE),FALSE),FALSE)
A3: 46264.625 | B3: 支出 | C3: 飲料 | D3: 588 | F3: =TEXT(A3,"yyyy-mm") | G3: =IF(B3="支出",IFERROR(VLOOKUP(C3,設定!$A$2:$B$200,2,FALSE),"その他"),"") | H3: =IF(B3="支出",IFERROR(VLOOKUP(C3,設定!$A$2:$C$200,3,FALSE),FALSE),FALSE)
A4: 46264.625 | B4: 支出 | C4: 日用品 | D4: 1902 | F4: =TEXT(A4,"yyyy-mm") | G4: =IF(B4="支出",IFERROR(VLOOKUP(C4,設定!$A$2:$B$200,2,FALSE),"その他"),"") | H4: =IF(B4="支出",IFERROR(VLOOKUP(C4,設定!$A$2:$C$200,3,FALSE),FALSE),FALSE)
A5: 46264.625 | B5: 支出 | C5: 猫 | D5: 983 | F5: =TEXT(A5,"yyyy-mm") | G5: =IF(B5="支出",IFERROR(VLOOKUP(C5,設定!$A$2:$B$200,2,FALSE),"その他"),"") | H5: =IF(B5="支出",IFERROR(VLOOKUP(C5,設定!$A$2:$C$200,3,FALSE),FALSE),FALSE)
A6: 46264.625 | B6: 支出 | C6: 食費 | D6: 2239 | F6: =TEXT(A6,"yyyy-mm") | G6: =IF(B6="支出",IFERROR(VLOOKUP(C6,設定!$A$2:$B$200,2,FALSE),"その他"),"") | H6: =IF(B6="支出",IFERROR(VLOOKUP(C6,設定!$A$2:$C$200,3,FALSE),FALSE),FALSE)
A7: 46264.625 | B7: 支出 | C7: 乾燥機 | D7: 2800 | F7: =TEXT(A7,"yyyy-mm") | G7: =IF(B7="支出",IFERROR(VLOOKUP(C7,設定!$A$2:$B$200,2,FALSE),"その他"),"") | H7: =IF(B7="支出",IFERROR(VLOOKUP(C7,設定!$A$2:$C$200,3,FALSE),FALSE),FALSE)
A8: 46264.625 | B8: 収入 | C8: 生活費 | D8: 20000 | E8: 小より | F8: =TEXT(A8,"yyyy-mm") | G8: =IF(B8="支出",IFERROR(VLOOKUP(C8,設定!$A$2:$B$200,2,FALSE),"その他"),"") | H8: =IF(B8="支出",IFERROR(VLOOKUP(C8,設定!$A$2:$C$200,3,FALSE),FALSE),FALSE)
A9: 46263.625 | B9: 支出 | C9: 菓子 | D9: 2378 | F9: =TEXT(A9,"yyyy-mm") | G9: =IF(B9="支出",IFERROR(VLOOKUP(C9,設定!$A$2:$B$200,2,FALSE),"その他"),"") | H9: =IF(B9="支出",IFERROR(VLOOKUP(C9,設定!$A$2:$C$200,3,FALSE),FALSE),FALSE)
A10: 46263.625 | B10: 支出 | C10: 調味料 | D10: 225 | F10: =TEXT(A10,"yyyy-mm") | G10: =IF(B10="支出",IFERROR(VLOOKUP(C10,設定!$A$2:$B$200,2,FALSE),"その他"),"") | H10: =IF(B10="支出",IFERROR(VLOOKUP(C10,設定!$A$2:$C$200,3,FALSE),FALSE),FALSE)
A11: 46263.625 | B11: 支出 | C11: 惣菜・弁当 | D11: 4479 | F11: =TEXT(A11,"yyyy-mm") | G11: =IF(B11="支出",IFERROR(VLOOKUP(C11,設定!$A$2:$B$200,2,FALSE),"その他"),"") | H11: =IF(B11="支出",IFERROR(VLOOKUP(C11,設定!$A$2:$C$200,3,FALSE),FALSE),FALSE)
A12: 46263.625 | B12: 支出 | C12: 食費 | D12: 3000 | F12: =TEXT(A12,"yyyy-mm") | G12: =IF(B12="支出",IFERROR(VLOOKUP(C12,設定!$A$2:$B$200,2,FALSE),"その他"),"") | H12: =IF(B12="支出",IFERROR(VLOOKUP(C12,設定!$A$2:$C$200,3,FALSE),FALSE),FALSE)
A13: 46262.625 | B13: 支出 | C13: 乾燥機 | D13: 800 | F13: =TEXT(A13,"yyyy-mm") | G13: =IF(B13="支出",IFERROR(VLOOKUP(C13,設定!$A$2:$B$200,2,FALSE),"その他"),"") | H13: =IF(B13="支出",IFERROR(VLOOKUP(C13,設定!$A$2:$C$200,3,FALSE),FALSE),FALSE)
A14: 46262.625 | B14: 支出 | C14: 菓子 | D14: 301 | F14: =TEXT(A14,"yyyy-mm") | G14: =IF(B14="支出",IFERROR(VLOOKUP(C14,設定!$A$2:$B$200,2,FALSE),"その他"),"") | H14: =IF(B14="支出",IFERROR(VLOOKUP(C14,設定!$A$2:$C$200,3,FALSE),FALSE),FALSE)
A15: 46262.625 | B15: 支出 | C15: 惣菜・弁当 | D15: 2076 | F15: =TEXT(A15,"yyyy-mm") | G15: =IF(B15="支出",IFERROR(VLOOKUP(C15,設定!$A$2:$B$200,2,FALSE),"その他"),"") | H15: =IF(B15="支出",IFERROR(VLOOKUP(C15,設定!$A$2:$C$200,3,FALSE),FALSE),FALSE)
A16: 46262.625 | B16: 支出 | C16: 日用品 | D16: 130 | F16: =TEXT(A16,"yyyy-mm") | G16: =IF(B16="支出",IFERROR(VLOOKUP(C16,設定!$A$2:$B$200,2,FALSE),"その他"),"") | H16: =IF(B16="支出",IFERROR(VLOOKUP(C16,設定!$A$2:$C$200,3,FALSE),FALSE),FALSE)
A17: 46262.625 | B17: 支出 | C17: 食費 | D17: 2649 | F17: =TEXT(A17,"yyyy-mm") | G17: =IF(B17="支出",IFERROR(VLOOKUP(C17,設定!$A$2:$B$200,2,FALSE),"その他"),"") | H17: =IF(B17="支出",IFERROR(VLOOKUP(C17,設定!$A$2:$C$200,3,FALSE),FALSE),FALSE)
A18: 46262.625 | B18: 支出 | C18: 飲料 | D18: 2555 | F18: =TEXT(A18,"yyyy-mm") | G18: =IF(B18="支出",IFERROR(VLOOKUP(C18,設定!$A$2:$B$200,2,FALSE),"その他"),"") | H18: =IF(B18="支出",IFERROR(VLOOKUP(C18,設定!$A$2:$C$200,3,FALSE),FALSE),FALSE)
A19: 46262.625 | B19: 支出 | C19: その他 | D19: 6600 | E19: イオンカードで支払い（仕事用の本） | F19: =TEXT(A19,"yyyy-mm") | G19: =IF(B19="支出",IFERROR(VLOOKUP(C19,設定!$A$2:$B$200,2,FALSE),"その他"),"") | H19: =IF(B19="支出",IFERROR(VLOOKUP(C19,設定!$A$2:$C$200,3,FALSE),FALSE),FALSE)
A20: 46262.625 | B20: 支出 | C20: 娯楽 | D20: 1584 | E20: イオンカードで支払い | F20: =TEXT(A20,"yyyy-mm") | G20: =IF(B20="支出",IFERROR(VLOOKUP(C20,設定!$A$2:$B$200,2,FALSE),"その他"),"") | H20: =IF(B20="支出",IFERROR(VLOOKUP(C20,設定!$A$2:$C$200,3,FALSE),FALSE),FALSE)
A21: 46262.625 | B21: 支出 | C21: 猫 | D21: 3164 | E21: イオンカードで支払い | F21: =TEXT(A21,"yyyy-mm") | G21: =IF(B21="支出",IFERROR(VLOOKUP(C21,設定!$A$2:$B$200,2,FALSE),"その他"),"") | H21: =IF(B21="支出",IFERROR(VLOOKUP(C21,設定!$A$2:$C$200,3,FALSE),FALSE),FALSE)
A22: 46262.625 | B22: 支出 | C22: 菓子 | D22: 495 | E22: イオンカードで支払い | F22: =TEXT(A22,"yyyy-mm") | G22: =IF(B22="支出",IFERROR(VLOOKUP(C22,設定!$A$2:$B$200,2,FALSE),"その他"),"") | H22: =IF(B22="支出",IFERROR(VLOOKUP(C22,設定!$A$2:$C$200,3,FALSE),FALSE),FALSE)
A23: 46262.625 | B23: 支出 | C23: 惣菜・弁当 | D23: 1242 | E23: イオンカードで支払い | F23: =TEXT(A23,"yyyy-mm") | G23: =IF(B23="支出",IFERROR(VLOOKUP(C23,設定!$A$2:$B$200,2,FALSE),"その他"),"") | H23: =IF(B23="支出",IFERROR(VLOOKUP(C23,設定!$A$2:$C$200,3,FALSE),FALSE),FALSE)
A24: 46262.625 | B24: 支出 | C24: 飲料 | D24: 212 | E24: イオンカードで支払い | F24: =TEXT(A24,"yyyy-mm") | G24: =IF(B24="支出",IFERROR(VLOOKUP(C24,設定!$A$2:$B$200,2,FALSE),"その他"),"") | H24: =IF(B24="支出",IFERROR(VLOOKUP(C24,設定!$A$2:$C$200,3,FALSE),FALSE),FALSE)
A25: 46262.625 | B25: 収入 | C25: その他 | D25: 13295 | E25: イオンカードで支払い | F25: =TEXT(A25,"yyyy-mm") | G25: =IF(B25="支出",IFERROR(VLOOKUP(C25,設定!$A$2:$B$200,2,FALSE),"その他"),"") | H25: =IF(B25="支出",IFERROR(VLOOKUP(C25,設定!$A$2:$C$200,3,FALSE),FALSE),FALSE)
A26: 46261.625 | B26: 支出 | C26: 菓子 | D26: 881 | F26: =TEXT(A26,"yyyy-mm") | G26: =IF(B26="支出",IFERROR(VLOOKUP(C26,設定!$A$2:$B$200,2,FALSE),"その他"),"") | H26: =IF(B26="支出",IFERROR(VLOOKUP(C26,設定!$A$2:$C$200,3,FALSE),FALSE),FALSE)
A27: 46261.625 | B27: 支出 | C27: 日用品 | D27: 3416 | F27: =TEXT(A27,"yyyy-mm") | G27: =IF(B27="支出",IFERROR(VLOOKUP(C27,設定!$A$2:$B$200,2,FALSE),"その他"),"") | H27: =IF(B27="支出",IFERROR(VLOOKUP(C27,設定!$A$2:$C$200,3,FALSE),FALSE),FALSE)
A28: 46261.625 | B28: 支出 | C28: 食費 | D28: 932 | F28: =TEXT(A28,"yyyy-mm") | G28: =IF(B28="支出",IFERROR(VLOOKUP(C28,設定!$A$2:$B$200,2,FALSE),"その他"),"") | H28: =IF(B28="支出",IFERROR(VLOOKUP(C28,設定!$A$2:$C$200,3,FALSE),FALSE),FALSE)
A29: 46261.625 | B29: 支出 | C29: 飲料 | D29: 1296 | F29: =TEXT(A29,"yyyy-mm") | G29: =IF(B29="支出",IFERROR(VLOOKUP(C29,設定!$A$2:$B$200,2,FALSE),"その他"),"") | H29: =IF(B29="支出",IFERROR(VLOOKUP(C29,設定!$A$2:$C$200,3,FALSE),FALSE),FALSE)
A30: 46261.625 | B30: 支出 | C30: 交際費 | D30: 21380 | E30: お中元（郁登・道田・秀子） | F30: =TEXT(A30,"yyyy-mm") | G30: =IF(B30="支出",IFERROR(VLOOKUP(C30,設定!$A$2:$B$200,2,FALSE),"その他"),"") | H30: =IF(B30="支出",IFERROR(VLOOKUP(C30,設定!$A$2:$C$200,3,FALSE),FALSE),FALSE)
A31: 46261.625 | B31: 収入 | C31: 生活費 | D31: 40000 | E31: 小より | F31: =TEXT(A31,"yyyy-mm") | G31: =IF(B31="支出",IFERROR(VLOOKUP(C31,設定!$A$2:$B$200,2,FALSE),"その他"),"") | H31: =IF(B31="支出",IFERROR(VLOOKUP(C31,設定!$A$2:$C$200,3,FALSE),FALSE),FALSE)
A32: 46260.625 | B32: 支出 | C32: 食費 | D32: 6004 | E32: 重箱と巻き寿司セット | F32: =TEXT(A32,"yyyy-mm") | G32: =IF(B32="支出",IFERROR(VLOOKUP(C32,設定!$A$2:$B$200,2,FALSE),"その他"),"") | H32: =IF(B32="支出",IFERROR(VLOOKUP(C32,設定!$A$2:$C$200,3,FALSE),FALSE),FALSE)
A33: 46260.625 | B33: 支出 | C33: その他 | D33: 1934 | E33: 給与（多）より / 新聞 | F33: =TEXT(A33,"yyyy-mm") | G33: =IF(B33="支出",IFERROR(VLOOKUP(C33,設定!$A$2:$B$200,2,FALSE),"その他"),"") | H33: =IF(B33="支出",IFERROR(VLOOKUP(C33,設定!$A$2:$C$200,3,FALSE),FALSE),FALSE)
A34: 46260.625 | B34: 収入 | C34: その他 | D34: 1934 | E34: 給与（多）より / 新聞 | F34: =TEXT(A34,"yyyy-mm") | G34: =IF(B34="支出",IFERROR(VLOOKUP(C34,設定!$A$2:$B$200,2,FALSE),"その他"),"") | H34: =IF(B34="支出",IFERROR(VLOOKUP(C34,設定!$A$2:$C$200,3,FALSE),FALSE),FALSE)
A35: 46260.625 | B35: 支出 | C35: その他 | D35: 3619 | E35: 大きいより / ガソリン代 | F35: =TEXT(A35,"yyyy-mm") | G35: =IF(B35="支出",IFERROR(VLOOKUP(C35,設定!$A$2:$B$200,2,FALSE),"その他"),"") | H35: =IF(B35="支出",IFERROR(VLOOKUP(C35,設定!$A$2:$C$200,3,FALSE),FALSE),FALSE)
A36: 46260.625 | B36: 収入 | C36: その他 | D36: 3619 | E36: 大きいより / ガソリン代 | F36: =TEXT(A36,"yyyy-mm") | G36: =IF(B36="支出",IFERROR(VLOOKUP(C36,設定!$A$2:$B$200,2,FALSE),"その他"),"") | H36: =IF(B36="支出",IFERROR(VLOOKUP(C36,設定!$A$2:$C$200,3,FALSE),FALSE),FALSE)
A37: 46260.625 | B37: 支出 | C37: 保険 | D37: 14194 | E37: 大きいより | F37: =TEXT(A37,"yyyy-mm") | G37: =IF(B37="支出",IFERROR(VLOOKUP(C37,設定!$A$2:$B$200,2,FALSE),"その他"),"") | H37: =IF(B37="支出",IFERROR(VLOOKUP(C37,設定!$A$2:$C$200,3,FALSE),FALSE),FALSE)
A38: 46260.625 | B38: 収入 | C38: 保険 | D38: 14194 | E38: 大きいより | F38: =TEXT(A38,"yyyy-mm") | G38: =IF(B38="支出",IFERROR(VLOOKUP(C38,設定!$A$2:$B$200,2,FALSE),"その他"),"") | H38: =IF(B38="支出",IFERROR(VLOOKUP(C38,設定!$A$2:$C$200,3,FALSE),FALSE),FALSE)
A39: 46260.625 | B39: 支出 | C39: その他 | D39: 29110 | E39: OCS（サンエー） | F39: =TEXT(A39,"yyyy-mm") | G39: =IF(B39="支出",IFERROR(VLOOKUP(C39,設定!$A$2:$B$200,2,FALSE),"その他"),"") | H39: =IF(B39="支出",IFERROR(VLOOKUP(C39,設定!$A$2:$C$200,3,FALSE),FALSE),FALSE)
A40: 46260.625 | B40: 支出 | C40: その他 | D40: 600 | E40: OCS（Amazon） | F40: =TEXT(A40,"yyyy-mm") | G40: =IF(B40="支出",IFERROR(VLOOKUP(C40,設定!$A$2:$B$200,2,FALSE),"その他"),"") | H40: =IF(B40="支出",IFERROR(VLOOKUP(C40,設定!$A$2:$C$200,3,FALSE),FALSE),FALSE)
...

Sheet 予算
A1: 年月 | B1: カテゴリ | C1: 予算額 | D1: ラベル

Sheet 預金口座
A1: 口座名 | B1: 銀行名 | C1: 口座種別 | D1: 現在残高 | E1: 初期残高 | F1: メモ
A2: 大きい | B2: 海邦（大） | C2: 普通 | D2: 1607226 | E2: 0
A3: 小 | B3: 海邦（小） | C3: 普通 | D3: 487051 | E3: 0
A4: 琉銀（聡） | B4: 琉球（聡） | C4: 普通 | D4: 2488544 | E4: 0
A5: 会社 | B5: 海邦（会社） | C5: 普通 | D5: 937822 | E5: 0
A6: 多 | B6: 琉球（多） | C6: 普通 | D6: 42398 | E6: 0
A7: 給与（多） | B7: 海邦（多） | C7: 普通 | D7: 36103 | E7: 0

Sheet 口座明細
A1: 日付 | B1: 口座名 | C1: 種別 | D1: カテゴリ | E1: 出金 | F1: 入金 | G1: 残高 | H1: 摘要 | I1: 相手口座
A2: 46264.625 | B2: 会社 | C2: 出金 | D2: 社会保険 | E2: 83997 | G2: 951353
A3: 46264.625 | B3: 小 | C3: 出金 | D3: 生活費 | E3: 20000 | G3: 519051
A4: 46264.625 | B4: 小 | C4: 入金 | D4: 家賃 | F4: 55000 | G4: 539051
A5: 46261.625 | B5: 小 | C5: 出金 | D5: 生活費 | E5: 40000 | G5: 484051
A6: 46260.625 | B6: 多 | C6: 出金 | D6: 娯楽 | E6: 15357 | G6: 114088
A7: 46260.625 | B7: 多 | C7: 出金 | D7: 保険 | E7: 9034 | G7: 114088
A8: 46260.625 | B8: 多 | C8: 出金 | D8: 保険 | E8: 1908 | G8: 138479
A9: 46260.625 | B9: 給与（多） | C9: 出金 | D9: その他 | E9: 1934 | G9: 36103 | H9: 新聞
A10: 46260.625 | B10: 大きい | C10: 出金 | D10: その他 | E10: 3619 | G10: 1607226 | H10: ガソリン代
A11: 46260.625 | B11: 大きい | C11: 出金 | D11: 保険 | E11: 14194 | G11: 1610845
A12: 46260.625 | B12: 小 | C12: 出金 | D12: その他 | E12: 97999 | G12: 524051 | H12: OCS
A13: 46260.625 | B13: 小 | C13: 出金 | D13: その他 | E13: 56756 | G13: 622050 | H13: OCS
A14: 46260.625 | B14: 小 | C14: 出金 | D14: その他 | E14: 28100 | G14: 678806 | H14: オリコ（車ローン）
A15: 46260.625 | B15: 小 | C15: 出金 | D15: 生活費 | E15: 10000 | G15: 706906
A16: 46259.625 | B16: 給与（多） | C16: 出金 | D16: 娯楽 | E16: 11963 | G16: 38037 | H16: vpass
A17: 46258.625 | B17: 小 | C17: 出金 | D17: 通信費 | E17: 8176 | G17: 716906 | H17: KDDI
A18: 46257.625 | B18: 大きい | C18: 出金 | D18: 振込 | E18: 200000 | G18: 1625039 | H18: 琉銀（多）に140000 生活費に60000
A19: 46257.625 | B19: 多 | C19: 入金 | F19: 140000 | G19: 140387 | H19: 海銀大きいより
A20: 46256.625 | B20: 給与（多） | C20: 出金 | D20: 生活費 | E20: 10000 | G20: 50000
A21: 46255.625 | B21: 給与（多） | C21: 出金 | D21: 生活費 | E21: 10000 | G21: 60000
A22: 46253.625 | B22: 小 | C22: 出金 | D22: 生活費 | E22: 20000 | G22: 725082
A23: 46250.625 | B23: 琉銀（聡） | C23: 入金 | D23: 利息 | F23: 328 | G23: 2488644
A24: 46248.625 | B24: 大きい | C24: 入金 | D24: 利息 | F24: 3654 | G24: 1625039
A25: 46248.625 | B25: 会社 | C25: 入金 | D25: 利息 | F25: 1068 | G25: 1035350
A26: 46248.625 | B26: 小 | C26: 入金 | D26: 利息 | F26: 255 | G26: 745082
A27: 46247.625 | B27: 大きい | C27: 出金 | D27: その他 | E27: 120000 | G27: 1821385 | H27: 車検・車保険
A28: 46247.625 | B28: 小 | C28: 振込入金 | D28: 公共料金 | F28: 92783 | G28: 744827 | H28: 年金
A29: 46243.625 | B29: 給与（多） | C29: 入金 | D29: 給与 | F29: 70000 | G29: 70000
A30: 46243.625 | B30: 多 | C30: 出金 | D30: カード引落 | E30: 3225 | G30: 387 | H30: 保険
A31: 46243.625 | B31: 多 | C31: 入金 | D31: その他 | F31: 3612 | G31: 3612
A32: 46243.625 | B32: 会社 | C32: 出金 | D32: その他 | E32: 410000 | G32: 1034282
A33: 46243.625 | B33: 会社 | C33: 入金 | D33: 琉石 | F33: 594000 | G33: 1444282
A34: 46243.625 | B34: 会社 | C34: 入金 | D34: その他 | F34: 850282 | G34: 850282
A35: 46243.625 | B35: 琉銀（聡） | C35: 入金 | D35: その他 | F35: 2488316 | G35: 2488316
A36: 46243.625 | B36: 大きい | C36: 出金 | D36: 公共料金 | E36: 1190000 | G36: 1941385 | H36: 固定資産税・市県民税
A37: 46243.625 | B37: 大きい | C37: 出金 | D37: カード引落 | E37: 1590 | G37: 3131385 | H37: マルチVISA
A38: 46243.625 | B38: 大きい | C38: 入金 | D38: その他 | F38: 100000 | G38: 3132975
A39: 46243.625 | B39: 小 | C39: 出金 | D39: その他 | E39: 50000 | G39: 652044 | H39: 生活費
A40: 46243.625 | B40: 小 | C40: 入金 | D40: 給与 | F40: 200000 | G40: 702044

Sheet 設定
A1: 科目 | B1: 大区分 | C1: 集計対象
A2: 惣菜・弁当 | B2: 食料品 | C2: TRUE
A3: 飲料 | B3: 食料品 | C3: TRUE
A4: 日用品 | B4: 生活用品 | C4: TRUE
A5: 猫 | B5: ペット | C5: TRUE
A6: 食費 | B6: 食料品 | C6: TRUE
A7: 乾燥機 | B7: 生活用品 | C7: TRUE
A8: 菓子 | B8: 食料品 | C8: TRUE
A9: 調味料 | B9: 食料品 | C9: TRUE
A10: その他 | B10: その他 | C10: TRUE
A11: 娯楽 | B11: 娯楽・交際 | C11: TRUE
A12: 交際費 | B12: 娯楽・交際 | C12: TRUE
A13: 保険 | B13: 医療・保険 | C13: TRUE
... A21: カード引落 | B21: 金融 | C21: TRUE
A23: 大区分リスト (参考): | B23: 食料品 | C23: 生活用品 | D23: ペット | E23: 通信・情報 | F23: 公共・住居 | G23: 医療・保険 | H23: 娯楽・交際 | I23: 金融 | J23: その他

Sheet 集計
A1: A. 月別×大区分 支出額
A2: 年月 | B2: 食料品 | C2: 生活用品 | D2: ペット | E2: 通信・情報 | F2: 公共・住居 | G2: 医療・保険 | H2: 娯楽・交際 | I2: 金融 | J2: その他
A3: 2026-08 | B3: =SUMIFS('収支データ'!$D$2:$D$188,'収支データ'!$F$2:$F$188,$A3,'収支データ'!$G$2:$G$188,B$2,'収支データ'!$H$2:$H$188,TRUE) | C3: =SUMIFS('収支データ'!$D$2:$D$188,'収支データ'!$F$2:$F$188,$A3,'収支データ'!$G$2:$G$188,C$2,'収支データ'!$H$2:$H$188,TRUE) | D3: =SUMIFS('収支データ'!$D$2:$D$188,'収支データ'!$F$2:$F$188,$A3,'収支データ'!$G$2:$G$188,D$2,'収支データ'!$H$2:$H$188,TRUE) | E3: =SUMIFS('収支データ'!$D$2:$D$188,'収支データ'!$F$2:$F$188,$A3,'収支データ'!$G$2:$G$188,E$2,'収支データ'!$H$2:$H$188,TRUE) | F3: =SUMIFS('収支データ'!$D$2:$D$188,'収支データ'!$F$2:$F$188,$A3,'収支データ'!$G$2:$G$188,F$2,'収支データ'!$H$2:$H$188,TRUE) | G3: =SUMIFS('収支データ'!$D$2:$D$188,'収支データ'!$F$2:$F$188,$A3,'収支データ'!$G$2:$G$188,G$2,'収支データ'!$H$2:$H$188,TRUE) | H3: =SUMIFS('収支データ'!$D$2:$D$188,'収支データ'!$F$2:$F$188,$A3,'収支データ'!$G$2:$G$188,H$2,'収支データ'!$H$2:$H$188,TRUE) | I3: =SUMIFS('収支データ'!$D$2:$D$188,'収支データ'!$F$2:$F$188,$A3,'収支データ'!$G$2:$G$188,I$2,'収支データ'!$H$2:$H$188,TRUE) | J3: =SUMIFS('収支データ'!$D$2:$D$188,'収支データ'!$F$2:$F$188,$A3,'収支データ'!$G$2:$G$188,J$2,'収支データ'!$H$2:$H$188,TRUE)
A5: B. 月別×科目 支出額
A6: 年月 | B6: 惣菜・弁当 | C6: 飲料 | D6: 日用品 | E6: 猫 | F6: 食費 | G6: 乾燥機 | H6: 菓子 | I6: 調味料 | J6: その他 | K6: 娯楽 | L6: 交際費 | M6: 保険 | N6: 光熱費 | O6: 通信費 | P6: NHK | Q6: 医療費 | R6: 住居 | S6: 新聞 | T6: 公共料金 | U6: カード引落
A7: 2026-08 | B7: =SUMIFS('収支データ'!$D$2:$D$188,'収支データ'!$F$2:$F$188,$A7,'収支データ'!$C$2:$C$188,B$6,'収支データ'!$H$2:$H$188,TRUE) | C7: =SUMIFS('収支データ'!$D$2:$D$188,'収支データ'!$F$2:$F$188,$A7,'収支データ'!$C$2:$C$188,C$6,'収支データ'!$H$2:$H$188,TRUE) | D7: =SUMIFS('収支データ'!$D$2:$D$188,'収支データ'!$F$2:$F$188,$A7,'収支データ'!$C$2:$C$188,D$6,'収支データ'!$H$2:$H$188,TRUE) | E7: =SUMIFS('収支データ'!$D$2:$D$188,'収支データ'!$F$2:$F$188,$A7,'収支データ'!$C$2:$C$188,E$6,'収支データ'!$H$2:$H$188,TRUE) | F7: =SUMIFS('収支データ'!$D$2:$D$188,'収支データ'!$F$2:$F$188,$A7,'収支データ'!$C$2:$C$188,F$6,'収支データ'!$H$2:$H$188,TRUE) | G7: =SUMIFS('収支データ'!$D$2:$D$188,'収支データ'!$F$2:$F$188,$A7,'収支データ'!$C$2:$C$188,G$6,'収支データ'!$H$2:$H$188,TRUE) | H7: =SUMIFS('収支データ'!$D$2:$D$188,'収支データ'!$F$2:$F$188,$A7,'収支データ'!$C$2:$C$188,H$6,'収支データ'!$H$2:$H$188,TRUE) | I7: =SUMIFS('収支データ'!$D$2:$D$188,'収支データ'!$F$2:$F$188,$A7,'収支データ'!$C$2:$C$188,I$6,'収支データ'!$H$2:$H$188,TRUE) | ... U7: =SUMIFS('収支データ'!$D$2:$D$188,'収支データ'!$F$2:$F$188,$A7,'収支データ'!$C$2:$C$188,U$6,'収支データ'!$H$2:$H$188,TRUE)
A9: C. 期間合計
A10: 大区分 | B10: 合計支出 | D10: 科目 | E10: 合計支出
A11: 食料品 | B11: =SUM(B3:B3) | D11: 惣菜・弁当 | E11: =SUM(B7:B7)
A12: 生活用品 | B12: =SUM(C3:C3) | D12: 飲料 | E12: =SUM(C7:C7)
A13: ペット | B13: =SUM(D3:D3) | D13: 日用品 | E13: =SUM(D7:D7)
A14: 通信・情報 | B14: =SUM(E3:E3) | D14: 猫 | E14: =SUM(E7:E7)
A15: 公共・住居 | B15: =SUM(F3:F3) | D15: 食費 | E15: =SUM(F7:F7)
A16: 医療・保険 | B16: =SUM(G3:G3) | D16: 乾燥機 | E16: =SUM(G7:G7)
A17: 娯楽・交際 | B17: =SUM(H3:H3) | D17: 菓子 | E17: =SUM(H7:H7)
A18: 金融 | B18: =SUM(I3:I3) | D18: 調味料 | E18: =SUM(I7:I7)
A19: その他 | B19: =SUM(J3:J3) | D19: その他 | E19: =SUM(J7:J7)
D20: 娯楽 | E20: =SUM(K7:K7)
D21: 交際費 | E21: =SUM(L7:L7)
D22: 保険 | E22: =SUM(M7:M7)
D23: 光熱費 | E23: =SUM(N7:N7)
D24: 通信費 | E24: =SUM(O7:O7)
D25: NHK | E25: =SUM(P7:P7)
D26: 医療費 | E26: =SUM(Q7:Q7)
D27: 住居 | E27: =SUM(R7:R7)
D28: 新聞 | E28: =SUM(S7:S7)
D29: 公共料金 | E29: =SUM(T7:T7)
D30: カード引落 | E30: =SUM(U7:U7)

Sheet グラフ
A1: 家計簿レポート
A2: ※ グラフは「設定」シートの集計対象 (TRUE/FALSE) に連動します
